Watching for file changes with StatReloader
[30/Aug/2019 08:42:55] "GET /rango/ HTTP/1.1" 200 29
[30/Aug/2019 08:42:56] "GET /rango/ HTTP/1.1" 200 29
[30/Aug/2019 08:42:57] "GET /rango/ HTTP/1.1" 200 29
<<<<<<< HEAD
[30/Aug/2019 08:53:05] "GET /rango/ HTTP/1.1" 200 29
Not Found: /favicon.ico
[30/Aug/2019 08:53:06] "GET /favicon.ico HTTP/1.1" 404 2097
Not Found: /
[30/Aug/2019 09:17:21] "GET / HTTP/1.1" 404 2046
Not Found: /
[30/Aug/2019 09:32:10] "GET / HTTP/1.1" 404 2046
Not Found: /robots.txt
[30/Aug/2019 09:32:11] "GET /robots.txt HTTP/1.1" 404 2094
----------------------------------------
Exception happened during processing of request from ('82.221.105.7', 33512)
Traceback (most recent call last):
  File "/usr/lib/python3.6/socketserver.py", line 654, in process_request_thread
    self.finish_request(request, client_address)
  File "/usr/lib/python3.6/socketserver.py", line 364, in finish_request
    self.RequestHandlerClass(request, client_address, self)
  File "/usr/lib/python3.6/socketserver.py", line 724, in __init__
    self.handle()
  File "/usr/local/lib/python3.6/dist-packages/django/core/servers/basehttp.py", line 171, in handle
    self.handle_one_request()
  File "/usr/local/lib/python3.6/dist-packages/django/core/servers/basehttp.py", line 179, in handle_one_request
    self.raw_requestline = self.rfile.readline(65537)
  File "/usr/lib/python3.6/socket.py", line 586, in readinto
    return self._sock.recv_into(b)
ConnectionResetError: [Errno 104] Connection reset by peer
----------------------------------------
Not Found: /sitemap.xml
[30/Aug/2019 09:32:12] "GET /sitemap.xml HTTP/1.1" 404 2097
Not Found: /.well-known/security.txt
[30/Aug/2019 09:32:12] "GET /.well-known/security.txt HTTP/1.1" 404 2136
----------------------------------------
Exception happened during processing of request from ('82.221.105.7', 33546)
Traceback (most recent call last):
  File "/usr/lib/python3.6/socketserver.py", line 654, in process_request_thread
    self.finish_request(request, client_address)
  File "/usr/lib/python3.6/socketserver.py", line 364, in finish_request
    self.RequestHandlerClass(request, client_address, self)
  File "/usr/lib/python3.6/socketserver.py", line 724, in __init__
    self.handle()
  File "/usr/local/lib/python3.6/dist-packages/django/core/servers/basehttp.py", line 171, in handle
    self.handle_one_request()
  File "/usr/local/lib/python3.6/dist-packages/django/core/servers/basehttp.py", line 179, in handle_one_request
    self.raw_requestline = self.rfile.readline(65537)
  File "/usr/lib/python3.6/socket.py", line 586, in readinto
    return self._sock.recv_into(b)
ConnectionResetError: [Errno 104] Connection reset by peer
----------------------------------------
Not Found: /favicon.ico
[30/Aug/2019 09:32:13] "GET /favicon.ico HTTP/1.1" 404 2097
----------------------------------------
Exception happened during processing of request from ('82.221.105.7', 33621)
Traceback (most recent call last):
  File "/usr/lib/python3.6/socketserver.py", line 654, in process_request_thread
    self.finish_request(request, client_address)
  File "/usr/lib/python3.6/socketserver.py", line 364, in finish_request
    self.RequestHandlerClass(request, client_address, self)
  File "/usr/lib/python3.6/socketserver.py", line 724, in __init__
    self.handle()
  File "/usr/local/lib/python3.6/dist-packages/django/core/servers/basehttp.py", line 171, in handle
    self.handle_one_request()
  File "/usr/local/lib/python3.6/dist-packages/django/core/servers/basehttp.py", line 179, in handle_one_request
    self.raw_requestline = self.rfile.readline(65537)
  File "/usr/lib/python3.6/socket.py", line 586, in readinto
    return self._sock.recv_into(b)
ConnectionResetError: [Errno 104] Connection reset by peer
----------------------------------------
Not Found: /
[30/Aug/2019 10:00:51] "GET / HTTP/1.1" 404 2046
Not Found: /http:/clientapi.ipip.net/echo.php
[30/Aug/2019 10:14:12] "GET http://clientapi.ipip.net/echo.php?info=1234567890 HTTP/1.1" 404 1729
Not Found: /http:/www.baidu.com/cache/global/img/gs.gif
[30/Aug/2019 10:28:18] "GET http://www.baidu.com/cache/global/img/gs.gif HTTP/1.1" 404 1738
=======
>>>>>>> e95ae40b179d3eb696bea3fa8b71b07c9d31d42b
Watching for file changes with StatReloader
[01/Sep/2019 16:42:20] "GET /rango/about/ HTTP/1.1" 200 394
[01/Sep/2019 16:42:20] "GET /static/css/about.css HTTP/1.1" 200 102
[01/Sep/2019 16:42:21] "GET /rango/about/ HTTP/1.1" 200 394
[01/Sep/2019 16:42:21] "GET /static/css/about.css HTTP/1.1" 304 0
[01/Sep/2019 16:42:25] "GET /static/css/about.css HTTP/1.1" 304 0
[01/Sep/2019 16:43:10] "GET /rango/about/ HTTP/1.1" 200 394
[01/Sep/2019 16:43:10] "GET /static/css/about.css HTTP/1.1" 200 96
[01/Sep/2019 16:43:11] "GET /rango/about/ HTTP/1.1" 200 394
[01/Sep/2019 16:43:11] "GET /static/css/about.css HTTP/1.1" 304 0
[01/Sep/2019 16:43:12] "GET /rango/about/ HTTP/1.1" 200 394
[01/Sep/2019 16:43:12] "GET /static/css/about.css HTTP/1.1" 304 0
[01/Sep/2019 16:43:14] "GET /rango/about/ HTTP/1.1" 200 394
[01/Sep/2019 16:43:15] "GET /static/css/about.css HTTP/1.1" 304 0
[01/Sep/2019 16:43:16] "GET /static/css/about.css HTTP/1.1" 304 0
[01/Sep/2019 16:43:33] code 400, message Bad request version ('HTTP')
[01/Sep/2019 16:43:33] "GET ../../mnt/custom/ProductDefinition HTTP" 400 -
[01/Sep/2019 16:44:12] "GET /rango/about/ HTTP/1.1" 200 394
[01/Sep/2019 16:44:12] "GET /static/css/about.css HTTP/1.1" 200 81
[01/Sep/2019 16:44:15] "GET /rango/ HTTP/1.1" 200 594
[01/Sep/2019 16:44:15] "GET /static/css/base.css HTTP/1.1" 200 84
[01/Sep/2019 16:44:15] "GET /static/js/jquery.js HTTP/1.1" 404 1660
[01/Sep/2019 16:44:19] "GET /rango/about/ HTTP/1.1" 200 394
[01/Sep/2019 16:44:19] "GET /static/css/about.css HTTP/1.1" 304 0
/root/git-tutorial/mysite/tango_with_django_project/tango_with_django_project/settings.py changed, reloading.
Performing system checks...

System check identified no issues (0 silenced).
September 01, 2019 - 16:40:12
Django version 2.2.3, using settings 'tango_with_django_project.settings'
Starting development server at http://0:80/
Quit the server with CONTROL-C.
Watching for file changes with StatReloader
Watching for file changes with StatReloader
[01/Sep/2019 16:53:30] "GET /rango/about/ HTTP/1.1" 200 394
[01/Sep/2019 16:53:30] "GET /static/css/about.css HTTP/1.1" 304 0
[01/Sep/2019 16:53:32] "GET /rango/about/ HTTP/1.1" 200 394
[01/Sep/2019 17:15:51] code 400, message Bad request version ('HTTP')
[01/Sep/2019 17:15:51] "GET ../../mnt/custom/ProductDefinition HTTP" 400 -
Not Found: /
[01/Sep/2019 17:17:41] "GET / HTTP/1.1" 404 2173
Not Found: /
[01/Sep/2019 17:58:14] "GET / HTTP/1.1" 404 2173
Traceback (most recent call last):
  File "/usr/lib/python3.6/wsgiref/handlers.py", line 138, in run
    self.finish_response()
  File "/usr/lib/python3.6/wsgiref/handlers.py", line 180, in finish_response
    self.write(data)
  File "/usr/lib/python3.6/wsgiref/handlers.py", line 274, in write
    self.send_headers()
  File "/usr/lib/python3.6/wsgiref/handlers.py", line 332, in send_headers
    self.send_preamble()
  File "/usr/lib/python3.6/wsgiref/handlers.py", line 252, in send_preamble
    self._write(('HTTP/%s %s\r\n' % (self.http_version,self.status)).encode('iso-8859-1'))
  File "/usr/lib/python3.6/wsgiref/handlers.py", line 453, in _write
    result = self.stdout.write(data)
  File "/usr/lib/python3.6/socketserver.py", line 803, in write
    self._sock.sendall(b)
ConnectionResetError: [Errno 104] Connection reset by peer
[01/Sep/2019 17:58:14] "GET / HTTP/1.1" 500 59
----------------------------------------
Exception happened during processing of request from ('101.132.111.175', 49345)
Traceback (most recent call last):
  File "/usr/lib/python3.6/wsgiref/handlers.py", line 138, in run
    self.finish_response()
  File "/usr/lib/python3.6/wsgiref/handlers.py", line 180, in finish_response
    self.write(data)
  File "/usr/lib/python3.6/wsgiref/handlers.py", line 274, in write
    self.send_headers()
  File "/usr/lib/python3.6/wsgiref/handlers.py", line 332, in send_headers
    self.send_preamble()
  File "/usr/lib/python3.6/wsgiref/handlers.py", line 252, in send_preamble
    self._write(('HTTP/%s %s\r\n' % (self.http_version,self.status)).encode('iso-8859-1'))
  File "/usr/lib/python3.6/wsgiref/handlers.py", line 453, in _write
    result = self.stdout.write(data)
  File "/usr/lib/python3.6/socketserver.py", line 803, in write
    self._sock.sendall(b)
ConnectionResetError: [Errno 104] Connection reset by peer

During handling of the above exception, another exception occurred:

Traceback (most recent call last):
  File "/usr/lib/python3.6/wsgiref/handlers.py", line 141, in run
    self.handle_error()
  File "/usr/local/lib/python3.6/dist-packages/django/core/servers/basehttp.py", line 116, in handle_error
    super().handle_error()
  File "/usr/lib/python3.6/wsgiref/handlers.py", line 368, in handle_error
    self.finish_response()
  File "/usr/lib/python3.6/wsgiref/handlers.py", line 180, in finish_response
    self.write(data)
  File "/usr/lib/python3.6/wsgiref/handlers.py", line 274, in write
    self.send_headers()
  File "/usr/lib/python3.6/wsgiref/handlers.py", line 331, in send_headers
    if not self.origin_server or self.client_is_modern():
  File "/usr/lib/python3.6/wsgiref/handlers.py", line 344, in client_is_modern
    return self.environ['SERVER_PROTOCOL'].upper() != 'HTTP/0.9'
TypeError: 'NoneType' object is not subscriptable

During handling of the above exception, another exception occurred:

Traceback (most recent call last):
  File "/usr/lib/python3.6/socketserver.py", line 654, in process_request_thread
    self.finish_request(request, client_address)
  File "/usr/lib/python3.6/socketserver.py", line 364, in finish_request
    self.RequestHandlerClass(request, client_address, self)
  File "/usr/lib/python3.6/socketserver.py", line 724, in __init__
    self.handle()
  File "/usr/local/lib/python3.6/dist-packages/django/core/servers/basehttp.py", line 169, in handle
    self.handle_one_request()
  File "/usr/local/lib/python3.6/dist-packages/django/core/servers/basehttp.py", line 194, in handle_one_request
    handler.run(self.server.get_app())
  File "/usr/lib/python3.6/wsgiref/handlers.py", line 144, in run
    self.close()
  File "/usr/local/lib/python3.6/dist-packages/django/core/servers/basehttp.py", line 111, in close
    super().close()
  File "/usr/lib/python3.6/wsgiref/simple_server.py", line 35, in close
    self.status.split(' ',1)[0], self.bytes_sent
AttributeError: 'NoneType' object has no attribute 'split'
----------------------------------------
Not Found: /
[01/Sep/2019 17:58:15] "GET / HTTP/1.1" 404 2173
Traceback (most recent call last):
  File "/usr/lib/python3.6/wsgiref/handlers.py", line 138, in run
    self.finish_response()
  File "/usr/lib/python3.6/wsgiref/handlers.py", line 180, in finish_response
    self.write(data)
  File "/usr/lib/python3.6/wsgiref/handlers.py", line 274, in write
    self.send_headers()
  File "/usr/lib/python3.6/wsgiref/handlers.py", line 332, in send_headers
    self.send_preamble()
  File "/usr/lib/python3.6/wsgiref/handlers.py", line 252, in send_preamble
    self._write(('HTTP/%s %s\r\n' % (self.http_version,self.status)).encode('iso-8859-1'))
  File "/usr/lib/python3.6/wsgiref/handlers.py", line 453, in _write
    result = self.stdout.write(data)
  File "/usr/lib/python3.6/socketserver.py", line 803, in write
    self._sock.sendall(b)
ConnectionResetError: [Errno 104] Connection reset by peer
[01/Sep/2019 17:58:15] "GET / HTTP/1.1" 500 59
----------------------------------------
Exception happened during processing of request from ('101.132.111.175', 49348)
Traceback (most recent call last):
  File "/usr/lib/python3.6/wsgiref/handlers.py", line 138, in run
    self.finish_response()
  File "/usr/lib/python3.6/wsgiref/handlers.py", line 180, in finish_response
    self.write(data)
  File "/usr/lib/python3.6/wsgiref/handlers.py", line 274, in write
    self.send_headers()
  File "/usr/lib/python3.6/wsgiref/handlers.py", line 332, in send_headers
    self.send_preamble()
  File "/usr/lib/python3.6/wsgiref/handlers.py", line 252, in send_preamble
    self._write(('HTTP/%s %s\r\n' % (self.http_version,self.status)).encode('iso-8859-1'))
  File "/usr/lib/python3.6/wsgiref/handlers.py", line 453, in _write
    result = self.stdout.write(data)
  File "/usr/lib/python3.6/socketserver.py", line 803, in write
    self._sock.sendall(b)
ConnectionResetError: [Errno 104] Connection reset by peer

During handling of the above exception, another exception occurred:

Traceback (most recent call last):
  File "/usr/lib/python3.6/wsgiref/handlers.py", line 141, in run
    self.handle_error()
  File "/usr/local/lib/python3.6/dist-packages/django/core/servers/basehttp.py", line 116, in handle_error
    super().handle_error()
  File "/usr/lib/python3.6/wsgiref/handlers.py", line 368, in handle_error
    self.finish_response()
  File "/usr/lib/python3.6/wsgiref/handlers.py", line 180, in finish_response
    self.write(data)
  File "/usr/lib/python3.6/wsgiref/handlers.py", line 274, in write
    self.send_headers()
  File "/usr/lib/python3.6/wsgiref/handlers.py", line 331, in send_headers
    if not self.origin_server or self.client_is_modern():
  File "/usr/lib/python3.6/wsgiref/handlers.py", line 344, in client_is_modern
    return self.environ['SERVER_PROTOCOL'].upper() != 'HTTP/0.9'
TypeError: 'NoneType' object is not subscriptable

During handling of the above exception, another exception occurred:

Traceback (most recent call last):
  File "/usr/lib/python3.6/socketserver.py", line 654, in process_request_thread
    self.finish_request(request, client_address)
  File "/usr/lib/python3.6/socketserver.py", line 364, in finish_request
    self.RequestHandlerClass(request, client_address, self)
  File "/usr/lib/python3.6/socketserver.py", line 724, in __init__
    self.handle()
  File "/usr/local/lib/python3.6/dist-packages/django/core/servers/basehttp.py", line 169, in handle
    self.handle_one_request()
  File "/usr/local/lib/python3.6/dist-packages/django/core/servers/basehttp.py", line 194, in handle_one_request
    handler.run(self.server.get_app())
  File "/usr/lib/python3.6/wsgiref/handlers.py", line 144, in run
    self.close()
  File "/usr/local/lib/python3.6/dist-packages/django/core/servers/basehttp.py", line 111, in close
    super().close()
  File "/usr/lib/python3.6/wsgiref/simple_server.py", line 35, in close
    self.status.split(' ',1)[0], self.bytes_sent
AttributeError: 'NoneType' object has no attribute 'split'
----------------------------------------
[01/Sep/2019 18:05:09] code 400, message Bad HTTP/0.9 request type ('\x03\x00\x00/*à\x00\x00\x00\x00\x00Cookie:')
[01/Sep/2019 18:05:09] "  /*à     Cookie: mstshash=Administr" 400 -
Not Found: /favicon.ico
[01/Sep/2019 18:12:43] "GET /favicon.ico HTTP/1.1" 404 2224
Not Found: /favicon.ico
[01/Sep/2019 18:12:43] "GET /favicon.ico HTTP/1.1" 404 2224
Not Found: /
[01/Sep/2019 18:36:12] "GET / HTTP/1.1" 404 2173
Not Found: /
[01/Sep/2019 18:54:32] "GET / HTTP/1.1" 404 2173
Traceback (most recent call last):
  File "/usr/lib/python3.6/wsgiref/handlers.py", line 138, in run
    self.finish_response()
  File "/usr/lib/python3.6/wsgiref/handlers.py", line 180, in finish_response
    self.write(data)
  File "/usr/lib/python3.6/wsgiref/handlers.py", line 274, in write
    self.send_headers()
  File "/usr/lib/python3.6/wsgiref/handlers.py", line 332, in send_headers
    self.send_preamble()
  File "/usr/lib/python3.6/wsgiref/handlers.py", line 252, in send_preamble
    self._write(('HTTP/%s %s\r\n' % (self.http_version,self.status)).encode('iso-8859-1'))
  File "/usr/lib/python3.6/wsgiref/handlers.py", line 453, in _write
    result = self.stdout.write(data)
  File "/usr/lib/python3.6/socketserver.py", line 803, in write
    self._sock.sendall(b)
ConnectionResetError: [Errno 104] Connection reset by peer
[01/Sep/2019 18:54:32] "GET / HTTP/1.1" 500 59
----------------------------------------
Exception happened during processing of request from ('62.210.83.78', 36000)
Traceback (most recent call last):
  File "/usr/lib/python3.6/wsgiref/handlers.py", line 138, in run
    self.finish_response()
  File "/usr/lib/python3.6/wsgiref/handlers.py", line 180, in finish_response
    self.write(data)
  File "/usr/lib/python3.6/wsgiref/handlers.py", line 274, in write
    self.send_headers()
  File "/usr/lib/python3.6/wsgiref/handlers.py", line 332, in send_headers
    self.send_preamble()
  File "/usr/lib/python3.6/wsgiref/handlers.py", line 252, in send_preamble
    self._write(('HTTP/%s %s\r\n' % (self.http_version,self.status)).encode('iso-8859-1'))
  File "/usr/lib/python3.6/wsgiref/handlers.py", line 453, in _write
    result = self.stdout.write(data)
  File "/usr/lib/python3.6/socketserver.py", line 803, in write
    self._sock.sendall(b)
ConnectionResetError: [Errno 104] Connection reset by peer

During handling of the above exception, another exception occurred:

Traceback (most recent call last):
  File "/usr/lib/python3.6/wsgiref/handlers.py", line 141, in run
    self.handle_error()
  File "/usr/local/lib/python3.6/dist-packages/django/core/servers/basehttp.py", line 116, in handle_error
    super().handle_error()
  File "/usr/lib/python3.6/wsgiref/handlers.py", line 368, in handle_error
    self.finish_response()
  File "/usr/lib/python3.6/wsgiref/handlers.py", line 180, in finish_response
    self.write(data)
  File "/usr/lib/python3.6/wsgiref/handlers.py", line 274, in write
    self.send_headers()
  File "/usr/lib/python3.6/wsgiref/handlers.py", line 331, in send_headers
    if not self.origin_server or self.client_is_modern():
  File "/usr/lib/python3.6/wsgiref/handlers.py", line 344, in client_is_modern
    return self.environ['SERVER_PROTOCOL'].upper() != 'HTTP/0.9'
TypeError: 'NoneType' object is not subscriptable

During handling of the above exception, another exception occurred:

Traceback (most recent call last):
  File "/usr/lib/python3.6/socketserver.py", line 654, in process_request_thread
    self.finish_request(request, client_address)
  File "/usr/lib/python3.6/socketserver.py", line 364, in finish_request
    self.RequestHandlerClass(request, client_address, self)
  File "/usr/lib/python3.6/socketserver.py", line 724, in __init__
    self.handle()
  File "/usr/local/lib/python3.6/dist-packages/django/core/servers/basehttp.py", line 169, in handle
    self.handle_one_request()
  File "/usr/local/lib/python3.6/dist-packages/django/core/servers/basehttp.py", line 194, in handle_one_request
    handler.run(self.server.get_app())
  File "/usr/lib/python3.6/wsgiref/handlers.py", line 144, in run
    self.close()
  File "/usr/local/lib/python3.6/dist-packages/django/core/servers/basehttp.py", line 111, in close
    super().close()
  File "/usr/lib/python3.6/wsgiref/simple_server.py", line 35, in close
    self.status.split(' ',1)[0], self.bytes_sent
AttributeError: 'NoneType' object has no attribute 'split'
----------------------------------------
Not Found: /
[01/Sep/2019 19:08:17] "GET / HTTP/1.1" 404 2173
Not Found: /
[01/Sep/2019 19:29:03] "GET / HTTP/1.1" 404 2176
Not Found: /http:/www.baidu.com/cache/global/img/gs.gif
[01/Sep/2019 20:30:49] "GET http://www.baidu.com/cache/global/img/gs.gif HTTP/1.1" 404 1738
----------------------------------------
Exception happened during processing of request from ('80.82.70.187', 58985)
Traceback (most recent call last):
  File "/usr/lib/python3.6/socketserver.py", line 654, in process_request_thread
    self.finish_request(request, client_address)
  File "/usr/lib/python3.6/socketserver.py", line 364, in finish_request
    self.RequestHandlerClass(request, client_address, self)
  File "/usr/lib/python3.6/socketserver.py", line 724, in __init__
    self.handle()
  File "/usr/local/lib/python3.6/dist-packages/django/core/servers/basehttp.py", line 171, in handle
    self.handle_one_request()
  File "/usr/local/lib/python3.6/dist-packages/django/core/servers/basehttp.py", line 179, in handle_one_request
    self.raw_requestline = self.rfile.readline(65537)
  File "/usr/lib/python3.6/socket.py", line 586, in readinto
    return self._sock.recv_into(b)
ConnectionResetError: [Errno 104] Connection reset by peer
----------------------------------------
Not Found: /
[01/Sep/2019 20:57:27] "GET / HTTP/1.1" 404 2173
[01/Sep/2019 21:05:14] code 400, message Bad request version ('HTTP')
[01/Sep/2019 21:05:14] "GET ../../mnt/custom/ProductDefinition HTTP" 400 -
Not Found: /
[01/Sep/2019 21:05:56] "GET / HTTP/1.1" 404 2176
Not Found: /
[01/Sep/2019 21:51:51] "GET / HTTP/1.1" 404 2176
Not Found: /favicon.ico
[01/Sep/2019 21:53:56] "GET /favicon.ico HTTP/1.1" 404 2224
Not Found: /favicon.ico
[01/Sep/2019 21:53:56] "GET /favicon.ico HTTP/1.1" 404 2224
Not Found: /
[01/Sep/2019 22:09:04] "GET / HTTP/1.1" 404 2176
Not Found: /
[01/Sep/2019 22:22:48] "GET / HTTP/1.1" 404 2176
Not Found: /
[01/Sep/2019 22:53:20] "GET / HTTP/1.1" 404 2173
----------------------------------------
Exception happened during processing of request from ('27.24.190.202', 49235)
Traceback (most recent call last):
  File "/usr/lib/python3.6/socketserver.py", line 654, in process_request_thread
    self.finish_request(request, client_address)
  File "/usr/lib/python3.6/socketserver.py", line 364, in finish_request
    self.RequestHandlerClass(request, client_address, self)
  File "/usr/lib/python3.6/socketserver.py", line 724, in __init__
    self.handle()
  File "/usr/local/lib/python3.6/dist-packages/django/core/servers/basehttp.py", line 171, in handle
    self.handle_one_request()
  File "/usr/local/lib/python3.6/dist-packages/django/core/servers/basehttp.py", line 179, in handle_one_request
    self.raw_requestline = self.rfile.readline(65537)
  File "/usr/lib/python3.6/socket.py", line 586, in readinto
    return self._sock.recv_into(b)
ConnectionResetError: [Errno 104] Connection reset by peer
----------------------------------------
[01/Sep/2019 23:55:49] "GET /rango/ HTTP/1.1" 200 594
Not Found: /
[01/Sep/2019 23:58:21] "GET / HTTP/1.1" 404 2173
Not Found: /
[02/Sep/2019 00:16:08] "GET / HTTP/1.1" 404 2176
[02/Sep/2019 01:09:55] code 400, message Bad request version ('HTTP')
[02/Sep/2019 01:09:55] "GET ../../mnt/custom/ProductDefinition HTTP" 400 -
Not Found: /
[02/Sep/2019 01:46:40] "GET / HTTP/1.1" 404 2173
Not Found: /
[02/Sep/2019 02:13:27] "GET / HTTP/1.1" 404 2173
Not Found: /
[02/Sep/2019 02:38:50] "GET / HTTP/1.1" 404 2173
----------------------------------------
Exception happened during processing of request from ('94.74.176.21', 58347)
Traceback (most recent call last):
  File "/usr/lib/python3.6/socketserver.py", line 654, in process_request_thread
    self.finish_request(request, client_address)
  File "/usr/lib/python3.6/socketserver.py", line 364, in finish_request
    self.RequestHandlerClass(request, client_address, self)
  File "/usr/lib/python3.6/socketserver.py", line 724, in __init__
    self.handle()
  File "/usr/local/lib/python3.6/dist-packages/django/core/servers/basehttp.py", line 171, in handle
    self.handle_one_request()
  File "/usr/local/lib/python3.6/dist-packages/django/core/servers/basehttp.py", line 179, in handle_one_request
    self.raw_requestline = self.rfile.readline(65537)
  File "/usr/lib/python3.6/socket.py", line 586, in readinto
    return self._sock.recv_into(b)
ConnectionResetError: [Errno 104] Connection reset by peer
----------------------------------------
Not Found: /
[02/Sep/2019 02:41:20] "GET / HTTP/1.1" 404 2176
Not Found: /
[02/Sep/2019 02:47:35] "GET / HTTP/1.1" 404 2173
Not Found: /setup.cgi
[02/Sep/2019 02:49:20] "GET /setup.cgi?next_file=netgear.cfg&todo=syscmd&cmd=busybox&curpath=/&currentsetting.htm=1 HTTP/1.1" 404 2320
----------------------------------------
Exception happened during processing of request from ('172.218.157.37', 33234)
Traceback (most recent call last):
  File "/usr/lib/python3.6/socketserver.py", line 654, in process_request_thread
    self.finish_request(request, client_address)
  File "/usr/lib/python3.6/socketserver.py", line 364, in finish_request
    self.RequestHandlerClass(request, client_address, self)
  File "/usr/lib/python3.6/socketserver.py", line 724, in __init__
    self.handle()
  File "/usr/local/lib/python3.6/dist-packages/django/core/servers/basehttp.py", line 171, in handle
    self.handle_one_request()
  File "/usr/local/lib/python3.6/dist-packages/django/core/servers/basehttp.py", line 179, in handle_one_request
    self.raw_requestline = self.rfile.readline(65537)
  File "/usr/lib/python3.6/socket.py", line 586, in readinto
    return self._sock.recv_into(b)
ConnectionResetError: [Errno 104] Connection reset by peer
----------------------------------------
Not Found: /setup.cgi
[02/Sep/2019 02:54:34] "GET /setup.cgi?next_file=netgear.cfg&todo=syscmd&cmd=busybox&curpath=/&currentsetting.htm=1 HTTP/1.1" 404 2320
----------------------------------------
Exception happened during processing of request from ('81.161.213.252', 46987)
Traceback (most recent call last):
  File "/usr/lib/python3.6/socketserver.py", line 654, in process_request_thread
    self.finish_request(request, client_address)
  File "/usr/lib/python3.6/socketserver.py", line 364, in finish_request
    self.RequestHandlerClass(request, client_address, self)
  File "/usr/lib/python3.6/socketserver.py", line 724, in __init__
    self.handle()
  File "/usr/local/lib/python3.6/dist-packages/django/core/servers/basehttp.py", line 171, in handle
    self.handle_one_request()
  File "/usr/local/lib/python3.6/dist-packages/django/core/servers/basehttp.py", line 179, in handle_one_request
    self.raw_requestline = self.rfile.readline(65537)
  File "/usr/lib/python3.6/socket.py", line 586, in readinto
    return self._sock.recv_into(b)
ConnectionResetError: [Errno 104] Connection reset by peer
----------------------------------------
Not Found: /
[02/Sep/2019 03:08:12] "GET / HTTP/1.1" 404 2176
[02/Sep/2019 04:55:20] code 400, message Bad request version ('HTTP')
[02/Sep/2019 04:55:20] "GET ../../mnt/custom/ProductDefinition HTTP" 400 -
Not Found: /
[02/Sep/2019 04:59:17] "GET / HTTP/1.1" 404 2176
Not Found: /
[02/Sep/2019 05:09:25] "GET / HTTP/1.1" 404 2173
Not Found: /
[02/Sep/2019 05:19:32] "OPTIONS / HTTP/1.1" 404 2177
Not Found: /
[02/Sep/2019 05:56:58] "GET / HTTP/1.1" 404 2173
Not Found: /
[02/Sep/2019 06:01:39] "GET / HTTP/1.1" 404 2176
Not Found: /http:/www.baidu.com/cache/global/img/gs.gif
[02/Sep/2019 06:30:38] "GET http://www.baidu.com/cache/global/img/gs.gif HTTP/1.1" 404 1738
----------------------------------------
Exception happened during processing of request from ('80.82.70.187', 56088)
Traceback (most recent call last):
  File "/usr/lib/python3.6/socketserver.py", line 654, in process_request_thread
    self.finish_request(request, client_address)
  File "/usr/lib/python3.6/socketserver.py", line 364, in finish_request
    self.RequestHandlerClass(request, client_address, self)
  File "/usr/lib/python3.6/socketserver.py", line 724, in __init__
    self.handle()
  File "/usr/local/lib/python3.6/dist-packages/django/core/servers/basehttp.py", line 171, in handle
    self.handle_one_request()
  File "/usr/local/lib/python3.6/dist-packages/django/core/servers/basehttp.py", line 179, in handle_one_request
    self.raw_requestline = self.rfile.readline(65537)
  File "/usr/lib/python3.6/socket.py", line 586, in readinto
    return self._sock.recv_into(b)
ConnectionResetError: [Errno 104] Connection reset by peer
----------------------------------------
Not Found: /
[02/Sep/2019 06:38:13] "GET / HTTP/1.1" 404 2173
Not Found: /
[02/Sep/2019 07:09:53] "GET / HTTP/1.1" 404 2173
[02/Sep/2019 07:19:16] "GET /static/images/game_pic/baolei.jpg HTTP/1.1" 200 1126925
[02/Sep/2019 08:45:24] code 400, message Bad HTTP/0.9 request type ('\x03\x00\x00/*à\x00\x00\x00\x00\x00Cookie:')
[02/Sep/2019 08:45:24] "  /*à     Cookie: mstshash=Administr" 400 -
[02/Sep/2019 08:46:20] code 400, message Bad request version ('HTTP')
[02/Sep/2019 08:46:20] "GET ../../mnt/custom/ProductDefinition HTTP" 400 -
Not Found: /
[02/Sep/2019 09:30:09] "GET / HTTP/1.1" 404 2173
Not Found: /
[02/Sep/2019 09:31:51] "GET / HTTP/1.1" 404 2173
Not Found: /
[02/Sep/2019 09:50:22] "GET / HTTP/1.1" 404 2173
Traceback (most recent call last):
  File "/usr/lib/python3.6/wsgiref/handlers.py", line 138, in run
    self.finish_response()
  File "/usr/lib/python3.6/wsgiref/handlers.py", line 180, in finish_response
    self.write(data)
  File "/usr/lib/python3.6/wsgiref/handlers.py", line 274, in write
    self.send_headers()
  File "/usr/lib/python3.6/wsgiref/handlers.py", line 332, in send_headers
    self.send_preamble()
  File "/usr/lib/python3.6/wsgiref/handlers.py", line 252, in send_preamble
    self._write(('HTTP/%s %s\r\n' % (self.http_version,self.status)).encode('iso-8859-1'))
  File "/usr/lib/python3.6/wsgiref/handlers.py", line 453, in _write
    result = self.stdout.write(data)
  File "/usr/lib/python3.6/socketserver.py", line 803, in write
    self._sock.sendall(b)
ConnectionResetError: [Errno 104] Connection reset by peer
[02/Sep/2019 09:50:22] "GET / HTTP/1.1" 500 59
----------------------------------------
Exception happened during processing of request from ('54.202.94.161', 37812)
Traceback (most recent call last):
  File "/usr/lib/python3.6/wsgiref/handlers.py", line 138, in run
    self.finish_response()
  File "/usr/lib/python3.6/wsgiref/handlers.py", line 180, in finish_response
    self.write(data)
  File "/usr/lib/python3.6/wsgiref/handlers.py", line 274, in write
    self.send_headers()
  File "/usr/lib/python3.6/wsgiref/handlers.py", line 332, in send_headers
    self.send_preamble()
  File "/usr/lib/python3.6/wsgiref/handlers.py", line 252, in send_preamble
    self._write(('HTTP/%s %s\r\n' % (self.http_version,self.status)).encode('iso-8859-1'))
  File "/usr/lib/python3.6/wsgiref/handlers.py", line 453, in _write
    result = self.stdout.write(data)
  File "/usr/lib/python3.6/socketserver.py", line 803, in write
    self._sock.sendall(b)
ConnectionResetError: [Errno 104] Connection reset by peer

During handling of the above exception, another exception occurred:

Traceback (most recent call last):
  File "/usr/lib/python3.6/wsgiref/handlers.py", line 141, in run
    self.handle_error()
  File "/usr/local/lib/python3.6/dist-packages/django/core/servers/basehttp.py", line 116, in handle_error
    super().handle_error()
  File "/usr/lib/python3.6/wsgiref/handlers.py", line 368, in handle_error
    self.finish_response()
  File "/usr/lib/python3.6/wsgiref/handlers.py", line 180, in finish_response
    self.write(data)
  File "/usr/lib/python3.6/wsgiref/handlers.py", line 274, in write
    self.send_headers()
  File "/usr/lib/python3.6/wsgiref/handlers.py", line 331, in send_headers
    if not self.origin_server or self.client_is_modern():
  File "/usr/lib/python3.6/wsgiref/handlers.py", line 344, in client_is_modern
    return self.environ['SERVER_PROTOCOL'].upper() != 'HTTP/0.9'
TypeError: 'NoneType' object is not subscriptable

During handling of the above exception, another exception occurred:

Traceback (most recent call last):
  File "/usr/lib/python3.6/socketserver.py", line 654, in process_request_thread
    self.finish_request(request, client_address)
  File "/usr/lib/python3.6/socketserver.py", line 364, in finish_request
    self.RequestHandlerClass(request, client_address, self)
  File "/usr/lib/python3.6/socketserver.py", line 724, in __init__
    self.handle()
  File "/usr/local/lib/python3.6/dist-packages/django/core/servers/basehttp.py", line 169, in handle
    self.handle_one_request()
  File "/usr/local/lib/python3.6/dist-packages/django/core/servers/basehttp.py", line 194, in handle_one_request
    handler.run(self.server.get_app())
  File "/usr/lib/python3.6/wsgiref/handlers.py", line 144, in run
    self.close()
  File "/usr/local/lib/python3.6/dist-packages/django/core/servers/basehttp.py", line 111, in close
    super().close()
  File "/usr/lib/python3.6/wsgiref/simple_server.py", line 35, in close
    self.status.split(' ',1)[0], self.bytes_sent
AttributeError: 'NoneType' object has no attribute 'split'
----------------------------------------
Not Found: /
[02/Sep/2019 10:03:49] "GET / HTTP/1.1" 404 2173
Not Found: /
[02/Sep/2019 10:29:28] "GET / HTTP/1.0" 404 2182
Not Found: /zh-CN/SystemSetting/AuthMenuList
[02/Sep/2019 11:34:08] "GET /zh-CN/SystemSetting/AuthMenuList HTTP/1.1" 404 2287
Not Found: /
[02/Sep/2019 11:38:29] "GET / HTTP/1.1" 404 2173
/root/git-tutorial/mysite/tango_with_django_project/rango/models.py changed, reloading.
Performing system checks...

System check identified no issues (0 silenced).
September 01, 2019 - 16:51:58
Django version 2.2.3, using settings 'tango_with_django_project.settings'
Starting development server at http://0:80/
Quit the server with CONTROL-C.
Watching for file changes with StatReloader
Exception in thread django-main-thread:
Traceback (most recent call last):
  File "/usr/lib/python3.6/threading.py", line 916, in _bootstrap_inner
    self.run()
  File "/usr/lib/python3.6/threading.py", line 864, in run
    self._target(*self._args, **self._kwargs)
  File "/usr/local/lib/python3.6/dist-packages/django/utils/autoreload.py", line 54, in wrapper
    fn(*args, **kwargs)
  File "/usr/local/lib/python3.6/dist-packages/django/core/management/commands/runserver.py", line 109, in inner_run
    autoreload.raise_last_exception()
  File "/usr/local/lib/python3.6/dist-packages/django/utils/autoreload.py", line 77, in raise_last_exception
    raise _exception[1]
  File "/usr/local/lib/python3.6/dist-packages/django/core/management/__init__.py", line 337, in execute
    autoreload.check_errors(django.setup)()
  File "/usr/local/lib/python3.6/dist-packages/django/utils/autoreload.py", line 54, in wrapper
    fn(*args, **kwargs)
  File "/usr/local/lib/python3.6/dist-packages/django/__init__.py", line 24, in setup
    apps.populate(settings.INSTALLED_APPS)
  File "/usr/local/lib/python3.6/dist-packages/django/apps/registry.py", line 114, in populate
    app_config.import_models()
  File "/usr/local/lib/python3.6/dist-packages/django/apps/config.py", line 211, in import_models
    self.models_module = import_module(models_module_name)
  File "/usr/lib/python3.6/importlib/__init__.py", line 126, in import_module
    return _bootstrap._gcd_import(name[level:], package, level)
  File "<frozen importlib._bootstrap>", line 994, in _gcd_import
  File "<frozen importlib._bootstrap>", line 971, in _find_and_load
  File "<frozen importlib._bootstrap>", line 955, in _find_and_load_unlocked
  File "<frozen importlib._bootstrap>", line 665, in _load_unlocked
  File "<frozen importlib._bootstrap_external>", line 678, in exec_module
  File "<frozen importlib._bootstrap>", line 219, in _call_with_frames_removed
  File "/root/git-tutorial/mysite/tango_with_django_project/rango/models.py", line 4, in <module>
    class Category(models.Model):
  File "/root/git-tutorial/mysite/tango_with_django_project/rango/models.py", line 5, in Category
    name = models.CharField(max_length=128, unique=Ture)
NameError: name 'Ture' is not defined

/root/git-tutorial/mysite/tango_with_django_project/rango/models.py changed, reloading.
Watching for file changes with StatReloader
Exception in thread django-main-thread:
Traceback (most recent call last):
  File "/usr/lib/python3.6/threading.py", line 916, in _bootstrap_inner
    self.run()
  File "/usr/lib/python3.6/threading.py", line 864, in run
    self._target(*self._args, **self._kwargs)
  File "/usr/local/lib/python3.6/dist-packages/django/utils/autoreload.py", line 54, in wrapper
    fn(*args, **kwargs)
  File "/usr/local/lib/python3.6/dist-packages/django/core/management/commands/runserver.py", line 109, in inner_run
    autoreload.raise_last_exception()
  File "/usr/local/lib/python3.6/dist-packages/django/utils/autoreload.py", line 77, in raise_last_exception
    raise _exception[1]
  File "/usr/local/lib/python3.6/dist-packages/django/core/management/__init__.py", line 337, in execute
    autoreload.check_errors(django.setup)()
  File "/usr/local/lib/python3.6/dist-packages/django/utils/autoreload.py", line 54, in wrapper
    fn(*args, **kwargs)
  File "/usr/local/lib/python3.6/dist-packages/django/__init__.py", line 24, in setup
    apps.populate(settings.INSTALLED_APPS)
  File "/usr/local/lib/python3.6/dist-packages/django/apps/registry.py", line 114, in populate
    app_config.import_models()
  File "/usr/local/lib/python3.6/dist-packages/django/apps/config.py", line 211, in import_models
    self.models_module = import_module(models_module_name)
  File "/usr/lib/python3.6/importlib/__init__.py", line 126, in import_module
    return _bootstrap._gcd_import(name[level:], package, level)
  File "<frozen importlib._bootstrap>", line 994, in _gcd_import
  File "<frozen importlib._bootstrap>", line 971, in _find_and_load
  File "<frozen importlib._bootstrap>", line 955, in _find_and_load_unlocked
  File "<frozen importlib._bootstrap>", line 665, in _load_unlocked
  File "<frozen importlib._bootstrap_external>", line 678, in exec_module
  File "<frozen importlib._bootstrap>", line 219, in _call_with_frames_removed
  File "/root/git-tutorial/mysite/tango_with_django_project/rango/models.py", line 10, in <module>
    class Page(models.Model):
  File "/root/git-tutorial/mysite/tango_with_django_project/rango/models.py", line 11, in Page
    category = models.Foreignkey(Category)
AttributeError: module 'django.db.models' has no attribute 'Foreignkey'

/root/git-tutorial/mysite/tango_with_django_project/rango/models.py changed, reloading.
Watching for file changes with StatReloader
Exception in thread django-main-thread:
Traceback (most recent call last):
  File "/usr/lib/python3.6/threading.py", line 916, in _bootstrap_inner
    self.run()
  File "/usr/lib/python3.6/threading.py", line 864, in run
    self._target(*self._args, **self._kwargs)
  File "/usr/local/lib/python3.6/dist-packages/django/utils/autoreload.py", line 54, in wrapper
    fn(*args, **kwargs)
  File "/usr/local/lib/python3.6/dist-packages/django/core/management/commands/runserver.py", line 109, in inner_run
    autoreload.raise_last_exception()
  File "/usr/local/lib/python3.6/dist-packages/django/utils/autoreload.py", line 77, in raise_last_exception
    raise _exception[1]
  File "/usr/local/lib/python3.6/dist-packages/django/core/management/__init__.py", line 337, in execute
    autoreload.check_errors(django.setup)()
  File "/usr/local/lib/python3.6/dist-packages/django/utils/autoreload.py", line 54, in wrapper
    fn(*args, **kwargs)
  File "/usr/local/lib/python3.6/dist-packages/django/__init__.py", line 24, in setup
    apps.populate(settings.INSTALLED_APPS)
  File "/usr/local/lib/python3.6/dist-packages/django/apps/registry.py", line 114, in populate
    app_config.import_models()
  File "/usr/local/lib/python3.6/dist-packages/django/apps/config.py", line 211, in import_models
    self.models_module = import_module(models_module_name)
  File "/usr/lib/python3.6/importlib/__init__.py", line 126, in import_module
    return _bootstrap._gcd_import(name[level:], package, level)
  File "<frozen importlib._bootstrap>", line 994, in _gcd_import
  File "<frozen importlib._bootstrap>", line 971, in _find_and_load
  File "<frozen importlib._bootstrap>", line 955, in _find_and_load_unlocked
  File "<frozen importlib._bootstrap>", line 665, in _load_unlocked
  File "<frozen importlib._bootstrap_external>", line 678, in exec_module
  File "<frozen importlib._bootstrap>", line 219, in _call_with_frames_removed
  File "/root/git-tutorial/mysite/tango_with_django_project/rango/models.py", line 10, in <module>
    class Page(models.Model):
  File "/root/git-tutorial/mysite/tango_with_django_project/rango/models.py", line 11, in Page
    category = models.ForeignKey(Category)
TypeError: __init__() missing 1 required positional argument: 'on_delete'

/root/git-tutorial/mysite/tango_with_django_project/rango/models.py changed, reloading.
Watching for file changes with StatReloader
Exception in thread django-main-thread:
Traceback (most recent call last):
  File "/usr/lib/python3.6/threading.py", line 916, in _bootstrap_inner
    self.run()
  File "/usr/lib/python3.6/threading.py", line 864, in run
    self._target(*self._args, **self._kwargs)
  File "/usr/local/lib/python3.6/dist-packages/django/utils/autoreload.py", line 54, in wrapper
    fn(*args, **kwargs)
  File "/usr/local/lib/python3.6/dist-packages/django/core/management/commands/runserver.py", line 109, in inner_run
    autoreload.raise_last_exception()
  File "/usr/local/lib/python3.6/dist-packages/django/utils/autoreload.py", line 77, in raise_last_exception
    raise _exception[1]
  File "/usr/local/lib/python3.6/dist-packages/django/core/management/__init__.py", line 337, in execute
    autoreload.check_errors(django.setup)()
  File "/usr/local/lib/python3.6/dist-packages/django/utils/autoreload.py", line 54, in wrapper
    fn(*args, **kwargs)
  File "/usr/local/lib/python3.6/dist-packages/django/__init__.py", line 24, in setup
    apps.populate(settings.INSTALLED_APPS)
  File "/usr/local/lib/python3.6/dist-packages/django/apps/registry.py", line 114, in populate
    app_config.import_models()
  File "/usr/local/lib/python3.6/dist-packages/django/apps/config.py", line 211, in import_models
    self.models_module = import_module(models_module_name)
  File "/usr/lib/python3.6/importlib/__init__.py", line 126, in import_module
    return _bootstrap._gcd_import(name[level:], package, level)
  File "<frozen importlib._bootstrap>", line 994, in _gcd_import
  File "<frozen importlib._bootstrap>", line 971, in _find_and_load
  File "<frozen importlib._bootstrap>", line 955, in _find_and_load_unlocked
  File "<frozen importlib._bootstrap>", line 665, in _load_unlocked
  File "<frozen importlib._bootstrap_external>", line 678, in exec_module
  File "<frozen importlib._bootstrap>", line 219, in _call_with_frames_removed
  File "/root/git-tutorial/mysite/tango_with_django_project/rango/models.py", line 10, in <module>
    class Page(models.Model):
  File "/root/git-tutorial/mysite/tango_with_django_project/rango/models.py", line 11, in Page
    category = models.ForeignKey(Category)
TypeError: __init__() missing 1 required positional argument: 'on_delete'

/root/git-tutorial/mysite/tango_with_django_project/rango/models.py changed, reloading.
Watching for file changes with StatReloader
Exception in thread django-main-thread:
Traceback (most recent call last):
  File "/usr/lib/python3.6/threading.py", line 916, in _bootstrap_inner
    self.run()
  File "/usr/lib/python3.6/threading.py", line 864, in run
    self._target(*self._args, **self._kwargs)
  File "/usr/local/lib/python3.6/dist-packages/django/utils/autoreload.py", line 54, in wrapper
    fn(*args, **kwargs)
  File "/usr/local/lib/python3.6/dist-packages/django/core/management/commands/runserver.py", line 109, in inner_run
    autoreload.raise_last_exception()
  File "/usr/local/lib/python3.6/dist-packages/django/utils/autoreload.py", line 77, in raise_last_exception
    raise _exception[1]
  File "/usr/local/lib/python3.6/dist-packages/django/core/management/__init__.py", line 337, in execute
    autoreload.check_errors(django.setup)()
  File "/usr/local/lib/python3.6/dist-packages/django/utils/autoreload.py", line 54, in wrapper
    fn(*args, **kwargs)
  File "/usr/local/lib/python3.6/dist-packages/django/__init__.py", line 24, in setup
    apps.populate(settings.INSTALLED_APPS)
  File "/usr/local/lib/python3.6/dist-packages/django/apps/registry.py", line 114, in populate
    app_config.import_models()
  File "/usr/local/lib/python3.6/dist-packages/django/apps/config.py", line 211, in import_models
    self.models_module = import_module(models_module_name)
  File "/usr/lib/python3.6/importlib/__init__.py", line 126, in import_module
    return _bootstrap._gcd_import(name[level:], package, level)
  File "<frozen importlib._bootstrap>", line 994, in _gcd_import
  File "<frozen importlib._bootstrap>", line 971, in _find_and_load
  File "<frozen importlib._bootstrap>", line 955, in _find_and_load_unlocked
  File "<frozen importlib._bootstrap>", line 665, in _load_unlocked
  File "<frozen importlib._bootstrap_external>", line 678, in exec_module
  File "<frozen importlib._bootstrap>", line 219, in _call_with_frames_removed
  File "/root/git-tutorial/mysite/tango_with_django_project/rango/models.py", line 10, in <module>
    class Page(models.Model):
  File "/root/git-tutorial/mysite/tango_with_django_project/rango/models.py", line 12, in Page
    title = models.CharField(max_lenght=128)
  File "/usr/local/lib/python3.6/dist-packages/django/db/models/fields/__init__.py", line 1037, in __init__
    super().__init__(*args, **kwargs)
TypeError: __init__() got an unexpected keyword argument 'max_lenght'

/root/git-tutorial/mysite/tango_with_django_project/tango_with_django_project/settings.py changed, reloading.
Watching for file changes with StatReloader
[02/Sep/2019 13:01:22] "GET /rango/ HTTP/1.1" 200 594
[02/Sep/2019 13:01:22] "GET /static/js/jquery.js HTTP/1.1" 404 1660
[02/Sep/2019 13:01:22] "GET /static/css/base.css HTTP/1.1" 304 0
Not Found: /favicon.ico
[02/Sep/2019 13:01:23] "GET /favicon.ico HTTP/1.1" 404 2224
[02/Sep/2019 13:01:29] "GET /admin HTTP/1.1" 301 0
[02/Sep/2019 13:01:29] "GET /admin/ HTTP/1.1" 302 0
[02/Sep/2019 13:01:29] "GET /admin/login/?next=/admin/ HTTP/1.1" 200 1821
[02/Sep/2019 13:01:29] "GET /static/admin/css/login.css HTTP/1.1" 200 1233
[02/Sep/2019 13:01:29] "GET /static/admin/css/base.css HTTP/1.1" 200 16378
[02/Sep/2019 13:01:29] "GET /static/admin/css/responsive.css HTTP/1.1" 200 17944
[02/Sep/2019 13:01:29] "GET /static/admin/css/fonts.css HTTP/1.1" 200 423
[02/Sep/2019 13:01:29] "GET /static/admin/fonts/Roboto-Light-webfont.woff HTTP/1.1" 200 85692
[02/Sep/2019 13:01:29] "GET /static/admin/fonts/Roboto-Regular-webfont.woff HTTP/1.1" 200 85876
[02/Sep/2019 13:01:31] "POST /admin/login/?next=/admin/ HTTP/1.1" 302 0
[02/Sep/2019 13:01:31] "GET /admin/ HTTP/1.1" 200 3001
[02/Sep/2019 13:01:31] "GET /static/admin/css/dashboard.css HTTP/1.1" 200 412
[02/Sep/2019 13:01:31] "GET /static/admin/img/icon-addlink.svg HTTP/1.1" 200 331
[02/Sep/2019 13:01:31] "GET /static/admin/img/icon-changelink.svg HTTP/1.1" 200 380
[02/Sep/2019 13:01:31] "GET /static/admin/fonts/Roboto-Bold-webfont.woff HTTP/1.1" 200 86184
/root/git-tutorial/mysite/tango_with_django_project/rango/admin.py changed, reloading.
Performing system checks...

System check identified no issues (0 silenced).
September 02, 2019 - 12:53:14
Django version 2.2.3, using settings 'tango_with_django_project.settings'
Starting development server at http://0:80/
Quit the server with CONTROL-C.
Watching for file changes with StatReloader
Watching for file changes with StatReloader
[02/Sep/2019 22:27:11] "GET /rango/ HTTP/1.1" 200 655
[02/Sep/2019 22:27:12] "GET /static/js/jquery.js HTTP/1.1" 404 1660
[02/Sep/2019 22:46:18] code 400, message Bad request version ('HTTP')
[02/Sep/2019 22:46:18] "GET ../../mnt/custom/ProductDefinition HTTP" 400 -
Not Found: /
[02/Sep/2019 23:02:48] "GET / HTTP/1.1" 404 2173
Not Found: /
[02/Sep/2019 23:21:18] "GET / HTTP/1.1" 404 2173
----------------------------------------
Exception happened during processing of request from ('98.246.45.94', 47511)
Traceback (most recent call last):
  File "/usr/lib/python3.6/socketserver.py", line 654, in process_request_thread
    self.finish_request(request, client_address)
  File "/usr/lib/python3.6/socketserver.py", line 364, in finish_request
    self.RequestHandlerClass(request, client_address, self)
  File "/usr/lib/python3.6/socketserver.py", line 724, in __init__
    self.handle()
  File "/usr/local/lib/python3.6/dist-packages/django/core/servers/basehttp.py", line 171, in handle
    self.handle_one_request()
  File "/usr/local/lib/python3.6/dist-packages/django/core/servers/basehttp.py", line 179, in handle_one_request
    self.raw_requestline = self.rfile.readline(65537)
  File "/usr/lib/python3.6/socket.py", line 586, in readinto
    return self._sock.recv_into(b)
ConnectionResetError: [Errno 104] Connection reset by peer
----------------------------------------
Not Found: /
[02/Sep/2019 23:31:53] "GET / HTTP/1.0" 404 2182
Not Found: /
[02/Sep/2019 23:48:37] "GET / HTTP/1.1" 404 2176
Not Found: /
[03/Sep/2019 00:16:19] "GET / HTTP/1.1" 404 2176
Not Found: /
[03/Sep/2019 00:19:38] "GET / HTTP/1.1" 404 2176
Not Found: /
[03/Sep/2019 00:20:08] "GET / HTTP/1.1" 404 2176
Not Found: /
[03/Sep/2019 01:55:27] "GET / HTTP/1.0" 404 2182
Not Found: /
[03/Sep/2019 02:03:10] "GET / HTTP/1.1" 404 2173
Not Found: /http:/www.baidu.com/cache/global/img/gs.gif
[03/Sep/2019 02:32:32] "GET http://www.baidu.com/cache/global/img/gs.gif HTTP/1.1" 404 1738
----------------------------------------
Exception happened during processing of request from ('80.82.70.187', 36778)
Traceback (most recent call last):
  File "/usr/lib/python3.6/socketserver.py", line 654, in process_request_thread
    self.finish_request(request, client_address)
  File "/usr/lib/python3.6/socketserver.py", line 364, in finish_request
    self.RequestHandlerClass(request, client_address, self)
  File "/usr/lib/python3.6/socketserver.py", line 724, in __init__
    self.handle()
  File "/usr/local/lib/python3.6/dist-packages/django/core/servers/basehttp.py", line 171, in handle
    self.handle_one_request()
  File "/usr/local/lib/python3.6/dist-packages/django/core/servers/basehttp.py", line 179, in handle_one_request
    self.raw_requestline = self.rfile.readline(65537)
  File "/usr/lib/python3.6/socket.py", line 586, in readinto
    return self._sock.recv_into(b)
ConnectionResetError: [Errno 104] Connection reset by peer
----------------------------------------
[03/Sep/2019 02:50:46] code 400, message Bad request version ('HTTP')
[03/Sep/2019 02:50:46] "GET ../../mnt/custom/ProductDefinition HTTP" 400 -
Not Found: /
[03/Sep/2019 02:51:20] "GET / HTTP/1.1" 404 2173
[03/Sep/2019 02:58:36] code 400, message Bad request version ('HTTP')
[03/Sep/2019 02:58:36] "GET ../../mnt/custom/ProductDefinition HTTP" 400 -
Not Found: /
[03/Sep/2019 03:28:32] "GET / HTTP/1.1" 404 2173
Not Found: /
[03/Sep/2019 04:07:24] "GET / HTTP/1.1" 404 2177
Not Found: /
[03/Sep/2019 04:11:41] "GET / HTTP/1.0" 404 2173
[03/Sep/2019 04:11:42] code 400, message Bad request version ('À\x14À')
[03/Sep/2019 04:11:42] You're accessing the development server over HTTPS, but it only supports HTTP.

Not Found: /
[03/Sep/2019 04:58:56] "GET / HTTP/1.1" 404 2173
Not Found: /
[03/Sep/2019 05:29:31] "GET / HTTP/1.1" 404 2173
Not Found: /
[03/Sep/2019 05:50:50] "GET / HTTP/1.1" 404 2176
[03/Sep/2019 06:06:03] code 400, message Bad request version ('HTTP')
[03/Sep/2019 06:06:03] "GET ../../mnt/custom/ProductDefinition HTTP" 400 -
Not Found: /
[03/Sep/2019 06:45:55] "GET / HTTP/1.1" 404 2173
Not Found: /
[03/Sep/2019 07:47:27] "GET / HTTP/1.1" 404 2173
Not Found: /
[03/Sep/2019 08:06:10] "GET / HTTP/1.0" 404 2176
[03/Sep/2019 08:17:21] code 400, message Bad request version ('HTTP')
[03/Sep/2019 08:17:21] "GET ../../mnt/custom/ProductDefinition HTTP" 400 -
Not Found: /
[03/Sep/2019 08:24:36] "GET / HTTP/1.1" 404 2173
[03/Sep/2019 10:37:31] code 400, message Bad request version ('HTTP')
[03/Sep/2019 10:37:31] "GET ../../mnt/custom/ProductDefinition HTTP" 400 -
Not Found: /secure/ContactAdministrators!default.jspa
[03/Sep/2019 10:45:56] "GET /secure/ContactAdministrators!default.jspa HTTP/1.1" 404 2314
Not Found: /
[03/Sep/2019 11:19:38] "GET / HTTP/1.1" 404 2173
Traceback (most recent call last):
  File "/usr/lib/python3.6/wsgiref/handlers.py", line 138, in run
    self.finish_response()
  File "/usr/lib/python3.6/wsgiref/handlers.py", line 180, in finish_response
    self.write(data)
  File "/usr/lib/python3.6/wsgiref/handlers.py", line 274, in write
    self.send_headers()
  File "/usr/lib/python3.6/wsgiref/handlers.py", line 332, in send_headers
    self.send_preamble()
  File "/usr/lib/python3.6/wsgiref/handlers.py", line 252, in send_preamble
    self._write(('HTTP/%s %s\r\n' % (self.http_version,self.status)).encode('iso-8859-1'))
  File "/usr/lib/python3.6/wsgiref/handlers.py", line 453, in _write
    result = self.stdout.write(data)
  File "/usr/lib/python3.6/socketserver.py", line 803, in write
    self._sock.sendall(b)
ConnectionResetError: [Errno 104] Connection reset by peer
[03/Sep/2019 11:19:38] "GET / HTTP/1.1" 500 59
----------------------------------------
Exception happened during processing of request from ('106.15.186.63', 47585)
Traceback (most recent call last):
  File "/usr/lib/python3.6/wsgiref/handlers.py", line 138, in run
    self.finish_response()
  File "/usr/lib/python3.6/wsgiref/handlers.py", line 180, in finish_response
    self.write(data)
  File "/usr/lib/python3.6/wsgiref/handlers.py", line 274, in write
    self.send_headers()
  File "/usr/lib/python3.6/wsgiref/handlers.py", line 332, in send_headers
    self.send_preamble()
  File "/usr/lib/python3.6/wsgiref/handlers.py", line 252, in send_preamble
    self._write(('HTTP/%s %s\r\n' % (self.http_version,self.status)).encode('iso-8859-1'))
  File "/usr/lib/python3.6/wsgiref/handlers.py", line 453, in _write
    result = self.stdout.write(data)
  File "/usr/lib/python3.6/socketserver.py", line 803, in write
    self._sock.sendall(b)
ConnectionResetError: [Errno 104] Connection reset by peer

During handling of the above exception, another exception occurred:

Traceback (most recent call last):
  File "/usr/lib/python3.6/wsgiref/handlers.py", line 141, in run
    self.handle_error()
  File "/usr/local/lib/python3.6/dist-packages/django/core/servers/basehttp.py", line 116, in handle_error
    super().handle_error()
  File "/usr/lib/python3.6/wsgiref/handlers.py", line 368, in handle_error
    self.finish_response()
  File "/usr/lib/python3.6/wsgiref/handlers.py", line 180, in finish_response
    self.write(data)
  File "/usr/lib/python3.6/wsgiref/handlers.py", line 274, in write
    self.send_headers()
  File "/usr/lib/python3.6/wsgiref/handlers.py", line 331, in send_headers
    if not self.origin_server or self.client_is_modern():
  File "/usr/lib/python3.6/wsgiref/handlers.py", line 344, in client_is_modern
    return self.environ['SERVER_PROTOCOL'].upper() != 'HTTP/0.9'
TypeError: 'NoneType' object is not subscriptable

During handling of the above exception, another exception occurred:

Traceback (most recent call last):
  File "/usr/lib/python3.6/socketserver.py", line 654, in process_request_thread
    self.finish_request(request, client_address)
  File "/usr/lib/python3.6/socketserver.py", line 364, in finish_request
    self.RequestHandlerClass(request, client_address, self)
  File "/usr/lib/python3.6/socketserver.py", line 724, in __init__
    self.handle()
  File "/usr/local/lib/python3.6/dist-packages/django/core/servers/basehttp.py", line 169, in handle
    self.handle_one_request()
  File "/usr/local/lib/python3.6/dist-packages/django/core/servers/basehttp.py", line 194, in handle_one_request
    handler.run(self.server.get_app())
  File "/usr/lib/python3.6/wsgiref/handlers.py", line 144, in run
    self.close()
  File "/usr/local/lib/python3.6/dist-packages/django/core/servers/basehttp.py", line 111, in close
    super().close()
  File "/usr/lib/python3.6/wsgiref/simple_server.py", line 35, in close
    self.status.split(' ',1)[0], self.bytes_sent
AttributeError: 'NoneType' object has no attribute 'split'
----------------------------------------
Not Found: /
[03/Sep/2019 11:56:44] "GET / HTTP/1.1" 404 2173
Not Found: /http:/www.baidu.com/cache/global/img/gs.gif
[03/Sep/2019 12:34:17] "GET http://www.baidu.com/cache/global/img/gs.gif HTTP/1.1" 404 1738
----------------------------------------
Exception happened during processing of request from ('80.82.70.187', 42224)
Traceback (most recent call last):
  File "/usr/lib/python3.6/socketserver.py", line 654, in process_request_thread
    self.finish_request(request, client_address)
  File "/usr/lib/python3.6/socketserver.py", line 364, in finish_request
    self.RequestHandlerClass(request, client_address, self)
  File "/usr/lib/python3.6/socketserver.py", line 724, in __init__
    self.handle()
  File "/usr/local/lib/python3.6/dist-packages/django/core/servers/basehttp.py", line 171, in handle
    self.handle_one_request()
  File "/usr/local/lib/python3.6/dist-packages/django/core/servers/basehttp.py", line 179, in handle_one_request
    self.raw_requestline = self.rfile.readline(65537)
  File "/usr/lib/python3.6/socket.py", line 586, in readinto
    return self._sock.recv_into(b)
ConnectionResetError: [Errno 104] Connection reset by peer
----------------------------------------
[03/Sep/2019 13:16:00] code 400, message Bad request version ('HTTP')
[03/Sep/2019 13:16:00] "GET ../../mnt/custom/ProductDefinition HTTP" 400 -
Not Found: /
[03/Sep/2019 13:24:10] "GET / HTTP/1.1" 404 2173
[03/Sep/2019 14:29:03] "GET /rango/ HTTP/1.1" 200 655
[03/Sep/2019 14:29:03] "GET /admin/login/?next=/admin/ HTTP/1.1" 200 1821
Not Found: /favicon.ico
[03/Sep/2019 14:29:04] "GET /favicon.ico HTTP/1.1" 404 2224
Not Found: /favicon.ico
[03/Sep/2019 14:29:04] "GET /favicon.ico HTTP/1.1" 404 2224
[03/Sep/2019 14:29:04] "GET /static/images/game_pic/baolei.jpg HTTP/1.1" 200 1126925
Not Found: /
[03/Sep/2019 15:22:49] "GET / HTTP/1.1" 404 2173
/root/git-tutorial/mysite/tango_with_django_project/rango/models.py changed, reloading.
Performing system checks...

System check identified no issues (0 silenced).
September 02, 2019 - 22:27:03
Django version 2.2.3, using settings 'tango_with_django_project.settings'
Starting development server at http://0:80/
Quit the server with CONTROL-C.
Watching for file changes with StatReloader
[03/Sep/2019 15:26:33] "GET /rango/ HTTP/1.1" 200 655
[03/Sep/2019 15:26:33] "GET /static/js/jquery.js HTTP/1.1" 404 1660
[03/Sep/2019 15:26:33] "GET /static/css/base.css HTTP/1.1" 304 0
Not Found: /favicon.ico
[03/Sep/2019 15:26:33] "GET /favicon.ico HTTP/1.1" 404 2224
[03/Sep/2019 15:26:42] "GET /admin/login/?next=/admin/ HTTP/1.1" 302 0
[03/Sep/2019 15:26:42] "GET /admin/ HTTP/1.1" 200 4109
[03/Sep/2019 15:26:42] "GET /static/admin/css/dashboard.css HTTP/1.1" 304 0
[03/Sep/2019 15:26:42] "GET /static/admin/css/base.css HTTP/1.1" 304 0
[03/Sep/2019 15:26:42] "GET /static/admin/css/responsive.css HTTP/1.1" 304 0
[03/Sep/2019 15:26:43] "GET /static/admin/css/fonts.css HTTP/1.1" 200 423
[03/Sep/2019 15:26:43] "GET /static/admin/img/icon-addlink.svg HTTP/1.1" 200 331
[03/Sep/2019 15:26:43] "GET /static/admin/img/icon-changelink.svg HTTP/1.1" 200 380
[03/Sep/2019 15:26:43] "GET /static/admin/fonts/Roboto-Regular-webfont.woff HTTP/1.1" 200 85876
[03/Sep/2019 15:26:43] "GET /static/admin/fonts/Roboto-Bold-webfont.woff HTTP/1.1" 200 86184
[03/Sep/2019 15:26:43] "GET /static/admin/fonts/Roboto-Light-webfont.woff HTTP/1.1" 200 85692
[03/Sep/2019 15:26:49] "GET /admin/rango/page/ HTTP/1.1" 200 7102
[03/Sep/2019 15:26:49] "GET /static/admin/js/vendor/jquery/jquery.js HTTP/1.1" 200 271817
[03/Sep/2019 15:26:49] "GET /static/admin/js/core.js HTTP/1.1" 200 7099
[03/Sep/2019 15:26:49] "GET /static/admin/js/jquery.init.js HTTP/1.1" 200 363
[03/Sep/2019 15:26:49] "GET /static/admin/css/changelists.css HTTP/1.1" 304 0
[03/Sep/2019 15:26:49] "GET /static/admin/js/admin/RelatedObjectLookups.js HTTP/1.1" 200 6918
[03/Sep/2019 15:26:49] "GET /admin/jsi18n/ HTTP/1.1" 200 7722
[03/Sep/2019 15:26:49] "GET /static/admin/js/actions.js HTTP/1.1" 200 6766
[03/Sep/2019 15:26:49] "GET /static/admin/js/urlify.js HTTP/1.1" 200 8941
[03/Sep/2019 15:26:49] "GET /static/admin/js/vendor/xregexp/xregexp.js HTTP/1.1" 200 128820
[03/Sep/2019 15:26:49] "GET /static/admin/js/prepopulate.js HTTP/1.1" 200 1530
[03/Sep/2019 15:26:49] "GET /static/admin/img/tooltag-add.svg HTTP/1.1" 200 331
[03/Sep/2019 15:26:54] "GET /admin/ HTTP/1.1" 200 4109
[03/Sep/2019 15:26:55] "GET /admin/rango/category/ HTTP/1.1" 200 4812
[03/Sep/2019 15:26:55] "GET /admin/jsi18n/ HTTP/1.1" 200 7722
[03/Sep/2019 15:27:18] "GET /admin/rango/category/add/ HTTP/1.1" 200 5426
[03/Sep/2019 15:27:18] "GET /static/admin/js/change_form.js HTTP/1.1" 200 712
[03/Sep/2019 15:27:18] "GET /static/admin/js/prepopulate_init.js HTTP/1.1" 200 495
[03/Sep/2019 15:27:18] "GET /static/admin/css/forms.css HTTP/1.1" 200 8518
[03/Sep/2019 15:27:18] "GET /admin/jsi18n/ HTTP/1.1" 200 7722
[03/Sep/2019 15:27:18] "GET /static/admin/css/widgets.css HTTP/1.1" 200 10340
[03/Sep/2019 15:27:34] "GET /admin/rango/ HTTP/1.1" 200 2855
[03/Sep/2019 15:27:36] "GET /admin/ HTTP/1.1" 200 4109
/root/git-tutorial/mysite/tango_with_django_project/rango/admin.py changed, reloading.
Performing system checks...

System check identified no issues (0 silenced).
September 03, 2019 - 15:23:14
Django version 2.2.3, using settings 'tango_with_django_project.settings'
Starting development server at http://0:80/
Quit the server with CONTROL-C.
Watching for file changes with StatReloader
[03/Sep/2019 15:30:24] "GET /admin/ HTTP/1.1" 200 4109
[03/Sep/2019 15:30:26] "GET /admin/ HTTP/1.1" 200 4109
[03/Sep/2019 15:30:27] "GET /admin/rango/category/ HTTP/1.1" 200 4812
[03/Sep/2019 15:30:27] "GET /admin/rango/category/ HTTP/1.1" 200 4812
[03/Sep/2019 15:30:27] "GET /admin/jsi18n/ HTTP/1.1" 200 7722
[03/Sep/2019 15:30:30] "GET /admin/ HTTP/1.1" 200 4109
[03/Sep/2019 15:30:31] "GET /admin/rango/category/ HTTP/1.1" 200 4812
[03/Sep/2019 15:30:31] "GET /admin/jsi18n/ HTTP/1.1" 200 7722
[03/Sep/2019 15:30:33] "GET /admin/rango/category/3/change/ HTTP/1.1" 200 5922
[03/Sep/2019 15:30:33] "GET /admin/jsi18n/ HTTP/1.1" 200 7722
[03/Sep/2019 15:30:35] "GET /admin/rango/category/ HTTP/1.1" 200 4812
[03/Sep/2019 15:30:37] "GET /admin/rango/category/add/ HTTP/1.1" 200 5661
[03/Sep/2019 15:30:37] "GET /admin/jsi18n/ HTTP/1.1" 200 7722
/root/git-tutorial/mysite/tango_with_django_project/rango/models.py changed, reloading.
Performing system checks...

System check identified no issues (0 silenced).
September 03, 2019 - 15:30:21
Django version 2.2.3, using settings 'tango_with_django_project.settings'
Starting development server at http://0:80/
Quit the server with CONTROL-C.
Watching for file changes with StatReloader
[03/Sep/2019 15:35:42] code 400, message Bad request version ('HTTP')
[03/Sep/2019 15:35:42] "GET ../../mnt/custom/ProductDefinition HTTP" 400 -
/root/git-tutorial/mysite/tango_with_django_project/rango/views.py changed, reloading.
Performing system checks...

System check identified no issues (0 silenced).
September 03, 2019 - 15:32:07
Django version 2.2.3, using settings 'tango_with_django_project.settings'
Starting development server at http://0:80/
Quit the server with CONTROL-C.
Watching for file changes with StatReloader
[03/Sep/2019 15:45:33] code 400, message Bad request version ('HTTP')
[03/Sep/2019 15:45:33] "GET ../../mnt/custom/ProductDefinition HTTP" 400 -
[03/Sep/2019 15:50:36] "GET /admin/ HTTP/1.1" 302 0
[03/Sep/2019 15:56:57] "GET /rango/ HTTP/1.1" 200 655
[03/Sep/2019 15:56:58] "GET /static/js/jquery.js HTTP/1.1" 404 1660
/root/git-tutorial/mysite/tango_with_django_project/rango/urls.py changed, reloading.
Performing system checks...

System check identified no issues (0 silenced).
September 03, 2019 - 15:39:40
Django version 2.2.3, using settings 'tango_with_django_project.settings'
Starting development server at http://0:80/
Quit the server with CONTROL-C.
Watching for file changes with StatReloader
/root/git-tutorial/mysite/tango_with_django_project/rango/urls.py changed, reloading.
Performing system checks...

System check identified no issues (0 silenced).
September 03, 2019 - 15:59:19
Django version 2.2.3, using settings 'tango_with_django_project.settings'
Starting development server at http://0:80/
Quit the server with CONTROL-C.
Watching for file changes with StatReloader
[03/Sep/2019 15:59:36] "GET /rango/ HTTP/1.1" 200 655
[03/Sep/2019 15:59:36] "GET /static/js/jquery.js HTTP/1.1" 404 1660
Not Found: /category/python
[03/Sep/2019 15:59:51] "GET /category/python HTTP/1.1" 404 2236
Not Found: /category
[03/Sep/2019 16:00:50] "GET /category HTTP/1.1" 404 2215
[03/Sep/2019 16:03:54] "GET /rango/ HTTP/1.1" 200 815
[03/Sep/2019 16:03:54] "GET /static/js/jquery.js HTTP/1.1" 404 1660
[03/Sep/2019 16:03:57] "GET /rango/category/python HTTP/1.1" 301 0
Internal Server Error: /rango/category/python/
Traceback (most recent call last):
  File "/usr/local/lib/python3.6/dist-packages/django/core/handlers/exception.py", line 34, in inner
    response = get_response(request)
  File "/usr/local/lib/python3.6/dist-packages/django/core/handlers/base.py", line 115, in _get_response
    response = self.process_exception_by_middleware(e, request)
  File "/usr/local/lib/python3.6/dist-packages/django/core/handlers/base.py", line 113, in _get_response
    response = wrapped_callback(request, *callback_args, **callback_kwargs)
  File "/root/git-tutorial/mysite/tango_with_django_project/rango/views.py", line 19, in show_category
    catgory = Category.objects.get(slug=category-name_slug)
NameError: name 'category' is not defined
[03/Sep/2019 16:03:57] "GET /rango/category/python/ HTTP/1.1" 500 64499
/root/git-tutorial/mysite/tango_with_django_project/rango/views.py changed, reloading.
Performing system checks...

System check identified no issues (0 silenced).
September 03, 2019 - 15:59:35
Django version 2.2.3, using settings 'tango_with_django_project.settings'
Starting development server at http://0:80/
Quit the server with CONTROL-C.
Watching for file changes with StatReloader
Internal Server Error: /rango/category/python/
Traceback (most recent call last):
  File "/usr/local/lib/python3.6/dist-packages/django/core/handlers/exception.py", line 34, in inner
    response = get_response(request)
  File "/usr/local/lib/python3.6/dist-packages/django/core/handlers/base.py", line 115, in _get_response
    response = self.process_exception_by_middleware(e, request)
  File "/usr/local/lib/python3.6/dist-packages/django/core/handlers/base.py", line 113, in _get_response
    response = wrapped_callback(request, *callback_args, **callback_kwargs)
  File "/root/git-tutorial/mysite/tango_with_django_project/rango/views.py", line 20, in show_category
    pages = Page.objects.filter(category=category)
NameError: name 'category' is not defined
[03/Sep/2019 16:05:28] "GET /rango/category/python/ HTTP/1.1" 500 64721
Not Found: /
[03/Sep/2019 16:33:19] "GET / HTTP/1.1" 404 2173
Internal Server Error: /rango/category/python/
Traceback (most recent call last):
  File "/usr/local/lib/python3.6/dist-packages/django/core/handlers/exception.py", line 34, in inner
    response = get_response(request)
  File "/usr/local/lib/python3.6/dist-packages/django/core/handlers/base.py", line 115, in _get_response
    response = self.process_exception_by_middleware(e, request)
  File "/usr/local/lib/python3.6/dist-packages/django/core/handlers/base.py", line 113, in _get_response
    response = wrapped_callback(request, *callback_args, **callback_kwargs)
  File "/root/git-tutorial/mysite/tango_with_django_project/rango/views.py", line 20, in show_category
    pages = Page.objects.filter(category=category)
NameError: name 'category' is not defined
[03/Sep/2019 16:34:58] "GET /rango/category/python/ HTTP/1.1" 500 64856
Watching for file changes with StatReloader
